<?xml version="1.0" ?>
<robot name="diff_drive_robot" xmlns:xacro="http://www.ros.org/wiki/xacro">

<xacro:include filename="$(find diff_drive_robot_description)/urdf/materials.xacro" />
<xacro:include filename="$(find diff_drive_robot_description)/urdf/diff_drive_robot.trans" />
<xacro:include filename="$(find diff_drive_robot_description)/urdf/diff_drive_robot.gazebo" />
<link name="base_link">
  <inertial>
    <origin xyz="0.002628369932205188 -1.1577803157919556e-17 0.03202679041651883" rpy="0 0 0"/>
    <mass value="0.8326833430570597"/>
    <inertia ixx="0.001511" iyy="0.002413" izz="0.003751" ixy="-0.0" iyz="0.0" ixz="-1.3e-05"/>
  </inertial>
  <visual>
    <origin xyz="0 0 0" rpy="0 0 0"/>
    <geometry>
      <mesh filename="package://diff_drive_robot_description/meshes/base_link.stl" scale="0.001 0.001 0.001"/>
    </geometry>
    <material name="yellow"/>
  </visual>
  <collision>
    <origin xyz="0 0 0" rpy="0 0 0"/>
    <geometry>
      <mesh filename="package://diff_drive_robot_description/meshes/base_link.stl" scale="0.001 0.001 0.001"/>
    </geometry>
  </collision>
</link>

<link name="right_wheel">
  <inertial>
    <origin xyz="-1.4932499681208355e-14 -0.01249999999999997 -3.469446951953614e-18" rpy="0 0 0"/>
    <mass value="0.06391177554646725"/>
    <inertia ixx="1.8e-05" iyy="3e-05" izz="1.8e-05" ixy="-0.0" iyz="0.0" ixz="0.0"/>
  </inertial>
  <visual>
    <origin xyz="0.065 0.085 -0.03" rpy="0 0 0"/>
    <geometry>
      <mesh filename="package://diff_drive_robot_description/meshes/right_wheel.stl" scale="0.001 0.001 0.001"/>
    </geometry>
    <material name="black"/>
  </visual>
  <collision>
    <origin xyz="0.065 0.085 -0.03" rpy="0 0 0"/>
    <geometry>
      <mesh filename="package://diff_drive_robot_description/meshes/right_wheel.stl" scale="0.001 0.001 0.001"/>
    </geometry>
  </collision>
</link>

<link name="left_wheel">
  <inertial>
    <origin xyz="-1.4932499681208355e-14 0.012499999999999997 -3.469446951953614e-18" rpy="0 0 0"/>
    <mass value="0.06391177554646725"/>
    <inertia ixx="1.8e-05" iyy="3e-05" izz="1.8e-05" ixy="-0.0" iyz="0.0" ixz="0.0"/>
  </inertial>
  <visual>
    <origin xyz="0.065 -0.085 -0.03" rpy="0 0 0"/>
    <geometry>
      <mesh filename="package://diff_drive_robot_description/meshes/left_wheel.stl" scale="0.001 0.001 0.001"/>
    </geometry>
    <material name="black"/>
  </visual>
  <collision>
    <origin xyz="0.065 -0.085 -0.03" rpy="0 0 0"/>
    <geometry>
      <mesh filename="package://diff_drive_robot_description/meshes/left_wheel.stl" scale="0.001 0.001 0.001"/>
    </geometry>
  </collision>
</link>

<link name="lidar">
  <inertial>
    <origin xyz="5.026061718855929e-18 0.0 0.0049999999999999906" rpy="0 0 0"/>
    <mass value="0.2219535209761188"/>
    <inertia ixx="5.2e-05" iyy="5.2e-05" izz="0.0001" ixy="0.0" iyz="-0.0" ixz="-0.0"/>
  </inertial>
  <visual>
    <origin xyz="-0.0 -0.0 -0.0675" rpy="0 0 0"/>
    <geometry>
      <mesh filename="package://diff_drive_robot_description/meshes/lidar.stl" scale="0.001 0.001 0.001"/>
    </geometry>
    <material name="red"/>
  </visual>
  <collision>
    <origin xyz="-0.0 -0.0 -0.0675" rpy="0 0 0"/>
    <geometry>
      <mesh filename="package://diff_drive_robot_description/meshes/lidar.stl" scale="0.001 0.001 0.001"/>
    </geometry>
  </collision>
</link>

<link name="caster">
  <inertial>
    <origin xyz="-0.03 0.0 -0.006750000000000004" rpy="0 0 0"/>
    <mass value="0.06936047530503713"/>
    <inertia ixx="5e-06" iyy="5e-06" izz="7e-06" ixy="-0.0" iyz="-0.0" ixz="0.0"/>
  </inertial>
  <visual>
    <origin xyz="-0.1 -0.0 -0.0175" rpy="0 0 0"/>
    <geometry>
      <mesh filename="package://diff_drive_robot_description/meshes/caster.stl" scale="0.001 0.001 0.001"/>
    </geometry>
    <material name="grey"/>
  </visual>
  <collision>
    <origin xyz="-0.1 -0.0 -0.0175" rpy="0 0 0"/>
    <geometry>
      <mesh filename="package://diff_drive_robot_description/meshes/caster.stl" scale="0.001 0.001 0.001"/>
    </geometry>
  </collision>
</link>

<link name="camera">
  <inertial>
    <origin xyz="0.0 -0.05 0.0049999999999999975" rpy="0 0 0"/>
    <mass value="0.0051124244897195505"/>
    <inertia ixx="0.0" iyy="0.0" izz="0.0" ixy="0.0" iyz="-0.0" ixz="-0.0"/>
  </inertial>
  <visual>
    <origin xyz="-0.075 -0.05 -0.0425" rpy="0 0 0"/>
    <geometry>
      <mesh filename="package://diff_drive_robot_description/meshes/camera.stl" scale="0.001 0.001 0.001"/>
    </geometry>
    <material name="blue"/>
  </visual>
  <collision>
    <origin xyz="-0.075 -0.05 -0.0425" rpy="0 0 0"/>
    <geometry>
      <mesh filename="package://diff_drive_robot_description/meshes/camera.stl" scale="0.001 0.001 0.001"/>
    </geometry>
  </collision>
</link>

<joint name="right_wheel_joint" type="continuous">
  <origin xyz="-0.065 -0.085 0.03" rpy="0 0 0"/>
  <parent link="base_link"/>
  <child link="right_wheel"/>
  <axis xyz="0.0 1.0 0.0"/>
</joint>

<joint name="left_wheel_joint" type="continuous">
  <origin xyz="-0.065 0.085 0.03" rpy="0 0 0"/>
  <parent link="base_link"/>
  <child link="left_wheel"/>
  <axis xyz="0.0 1.0 0.0"/>
</joint>

<joint name="lidar_joint" type="fixed">
  <origin xyz="0.0 0.0 0.0675" rpy="0 0 0"/>
  <parent link="base_link"/>
  <child link="lidar"/>
</joint>

<joint name="caster_joint" type="fixed">
  <origin xyz="0.1 0.0 0.0175" rpy="0 0 0"/>
  <parent link="base_link"/>
  <child link="caster"/>
</joint>

<joint name="camera_joint" type="fixed">
  <origin xyz="0.075 0.05 0.0425" rpy="0 0 0"/>
  <parent link="base_link"/>
  <child link="camera"/>
</joint>

</robot>
